Workbook

Sheet 使用說明
A1: 客服案件與服務品質資料 | B1: 範例 7｜客服案件與服務品質資料 | C1: 範例 7｜客服案件與服務品質資料 | D1: 範例 7｜客服案件與服務品質資料 | E1: 範例 7｜客服案件與服務品質資料 | F1: 範例 7｜客服案件與服務品質資料
A2: 藍色欄位是原始輸入資料；灰色欄位是系統自動產生的衍生資料，包含查表帶入、時間計算與條件判斷，並不都是數字運算。 | B2: 藍色欄位是原始輸入資料；灰色欄位是系統自動產生的衍生資料，包含查表帶入、時間計算與條件判斷，並不都是數字運算。 | C2: 藍色欄位是原始輸入資料；灰色欄位是系統自動產生的衍生資料，包含查表帶入、時間計算與條件判斷，並不都是數字運算。 | D2: 藍色欄位是原始輸入資料；灰色欄位是系統自動產生的衍生資料，包含查表帶入、時間計算與條件判斷，並不都是數字運算。 | E2: 藍色欄位是原始輸入資料；灰色欄位是系統自動產生的衍生資料，包含查表帶入、時間計算與條件判斷，並不都是數字運算。 | F2: 藍色欄位是原始輸入資料；灰色欄位是系統自動產生的衍生資料，包含查表帶入、時間計算與條件判斷，並不都是數字運算。
A3: **Chatgpt 請忽略此頁面**
A5: 項目 | B5: 內容
A6: 資料主題 | B6: 客服案件追蹤與服務品質
A7: 資料截止時間 | B7: 46204.375
A8: 資料性質 | B8: 所有人名、客戶編號、工單與回饋內容均為模擬資料
A10: 工作表 | B10: 主要內容 | C10: 資料角色 | D10: 使用提醒
A11: 客服工單 | B11: 案件、管道、問題類型、狀態與 SLA | C11: 主要分析明細 | D11: 灰色欄位為公式計算欄位
A12: 人員與團隊 | B12: 人員、團隊、專長與建議工作量 | C12: 主檔 | D12: 可依人員編號連接客服工單
A13: SLA標準（Service Level Agreement，服務水準協議） | B13: 各優先程度的回覆與結案時限 | C13: 規則表 | D13: 客服工單中的 SLA 欄位引用此表
A14: 滿意度調查 | B14: 結案後的評分與文字回饋 | C14: 調查明細 | D14: 可依工單編號連接客服工單
A15: 資料截止時間 | B15: 公式判斷未結案案件是否逾期的基準 | C15: 設定值 | D15: 如要延伸練習，可修改 B6
A17: 欄位類型 | B17: 顯示顏色 | C17: 包含欄位 | D17: 產生方式 | E17: 用途 | F17: 是否人工輸入
A18: 原始輸入欄位 | B18: 藍色／白色 | C18: 工單編號、時間、管道、問題、優先程度、人員、狀態等 | D18: 由客服系統或人員記錄 | E18: 保留案件實際發生的內容 | F18: 是
A19: 查表帶入欄位 | B19: 灰色 | C19: 負責團隊、兩個 SLA 上限、整體滿意度 | D19: 用識別欄位連接其他工作表後帶入 | E19: 避免在每筆工單重複輸入相同資料 | F19: 否
A20: 時間計算欄位 | B20: 灰色 | C20: 首次回覆分鐘、處理時間小時、目前等待小時 | D20: 由兩個日期時間相減 | E20: 把時間差轉成可比較的分鐘或小時 | F20: 否
A21: 條件判斷／整理欄位 | B21: 灰色 | C21: SLA狀態、調查回覆、服務月份 | D21: 依其他欄位判斷或轉換格式 | E21: 方便篩選、統計與製作儀表板 | F21: 否
A23: SLA 判斷步驟 | B23: 使用欄位 | C23: 資料從哪裡來 | D23: 產生結果 | E23: 已結案案件怎麼判斷 | F23: 未結案案件怎麼判斷
A24: 1. 取得服務標準 | B24: 優先程度 | C24: 客服工單 G 欄連接「SLA標準」 | D24: 首次回覆上限、結案上限 | E24: 套用對應優先程度的標準 | F24: 套用對應優先程度的標準
A25: 2. 計算回覆速度 | B25: 建立日期時間、首次回覆時間 | C25: 客服工單 B、K 欄 | D25: 首次回覆分鐘 | E25: K－B，結果必須小於等於回覆上限 | F25: K－B，結果必須小於等於回覆上限
A26: 3. 計算處理時間 | B26: 建立日期時間、結案時間 | C26: 客服工單 B、L 欄 | D26: 處理時間小時 | E26: L－B，結果必須小於等於結案上限 | F26: 尚未結案，因此改看目前等待小時
A27: 4. 計算目前等待 | B27: 資料截止時間、建立日期時間 | C27: 使用說明 B6、客服工單 B 欄 | D27: 目前等待小時 | E27: 已結案，顯示 0 | F27: 資料截止時間－B，必須小於等於結案上限
A28: 5. 產生 SLA 狀態 | B28: 實際時間、SLA上限、案件狀態 | C28: 客服工單 J、M～Q、V 欄 | D28: 達標／進行中／逾期 | E28: 回覆與結案兩項都未超時才是達標 | F28: 回覆或等待時間任一超時就是逾期，否則是進行中
A29: 重點 | B29: SLA同時檢查兩件事 | C29: 是否及時回覆＋是否及時完成 | D29: 服務時效結論 | E29: 不能只看結案時間 | F29: 不能因尚未結案就忽略首次回覆是否超時
... A53: 目前等待小時 | B53: 時間計算 | C53: 資料截止時間－建立日期時間 | D53: 只用於尚未結案案件；已結案顯示 0 | E53: 與結案上限比較是否已逾期 | F53: 待辦與逾期追蹤

Sheet 客服工單
A1: 客服工單明細 | B1: 客服工單明細 | C1: 客服工單明細 | D1: 客服工單明細 | E1: 客服工單明細 | F1: 客服工單明細 | G1: 客服工單明細 | H1: 客服工單明細 | I1: 客服工單明細 | J1: 客服工單明細 | K1: 客服工單明細 | L1: 客服工單明細 | M1: 客服工單明細 | N1: 客服工單明細 | O1: 客服工單明細 | P1: 客服工單明細 | Q1: 客服工單明細 | R1: 客服工單明細 | S1: 客服工單明細 | T1: 客服工單明細 | U1: 客服工單明細 | V1: 客服工單明細
A2: 藍色／白色為原始輸入欄位；灰色為系統自動產生欄位，包含查表帶入、時間計算與條件判斷。資料期間：2026-04-01～2026-06-30。 | B2: 藍色／白色為原始輸入欄位；灰色為系統自動產生欄位，包含查表帶入、時間計算與條件判斷。資料期間：2026-04-01～2026-06-30。 | C2: 藍色／白色為原始輸入欄位；灰色為系統自動產生欄位，包含查表帶入、時間計算與條件判斷。資料期間：2026-04-01～2026-06-30。 | D2: 藍色／白色為原始輸入欄位；灰色為系統自動產生欄位，包含查表帶入、時間計算與條件判斷。資料期間：2026-04-01～2026-06-30。 | E2: 藍色／白色為原始輸入欄位；灰色為系統自動產生欄位，包含查表帶入、時間計算與條件判斷。資料期間：2026-04-01～2026-06-30。 | F2: 藍色／白色為原始輸入欄位；灰色為系統自動產生欄位，包含查表帶入、時間計算與條件判斷。資料期間：2026-04-01～2026-06-30。 | G2: 藍色／白色為原始輸入欄位；灰色為系統自動產生欄位，包含查表帶入、時間計算與條件判斷。資料期間：2026-04-01～2026-06-30。 | H2: 藍色／白色為原始輸入欄位；灰色為系統自動產生欄位，包含查表帶入、時間計算與條件判斷。資料期間：2026-04-01～2026-06-30。 | I2: 藍色／白色為原始輸入欄位；灰色為系統自動產生欄位，包含查表帶入、時間計算與條件判斷。資料期間：2026-04-01～2026-06-30。 | J2: 藍色／白色為原始輸入欄位；灰色為系統自動產生欄位，包含查表帶入、時間計算與條件判斷。資料期間：2026-04-01～2026-06-30。 | K2: 藍色／白色為原始輸入欄位；灰色為系統自動產生欄位，包含查表帶入、時間計算與條件判斷。資料期間：2026-04-01～2026-06-30。 | L2: 藍色／白色為原始輸入欄位；灰色為系統自動產生欄位，包含查表帶入、時間計算與條件判斷。資料期間：2026-04-01～2026-06-30。 | M2: 藍色／白色為原始輸入欄位；灰色為系統自動產生欄位，包含查表帶入、時間計算與條件判斷。資料期間：2026-04-01～2026-06-30。 | N2: 藍色／白色為原始輸入欄位；灰色為系統自動產生欄位，包含查表帶入、時間計算與條件判斷。資料期間：2026-04-01～2026-06-30。 | O2: 藍色／白色為原始輸入欄位；灰色為系統自動產生欄位，包含查表帶入、時間計算與條件判斷。資料期間：2026-04-01～2026-06-30。 | P2: 藍色／白色為原始輸入欄位；灰色為系統自動產生欄位，包含查表帶入、時間計算與條件判斷。資料期間：2026-04-01～2026-06-30。 | Q2: 藍色／白色為原始輸入欄位；灰色為系統自動產生欄位，包含查表帶入、時間計算與條件判斷。資料期間：2026-04-01～2026-06-30。 | R2: 藍色／白色為原始輸入欄位；灰色為系統自動產生欄位，包含查表帶入、時間計算與條件判斷。資料期間：2026-04-01～2026-06-30。 | S2: 藍色／白色為原始輸入欄位；灰色為系統自動產生欄位，包含查表帶入、時間計算與條件判斷。資料期間：2026-04-01～2026-06-30。 | T2: 藍色／白色為原始輸入欄位；灰色為系統自動產生欄位，包含查表帶入、時間計算與條件判斷。資料期間：2026-04-01～2026-06-30。 | U2: 藍色／白色為原始輸入欄位；灰色為系統自動產生欄位，包含查表帶入、時間計算與條件判斷。資料期間：2026-04-01～2026-06-30。 | V2: 藍色／白色為原始輸入欄位；灰色為系統自動產生欄位，包含查表帶入、時間計算與條件判斷。資料期間：2026-04-01～2026-06-30。
A3: 工單編號 | B3: 建立日期時間 | C3: 客戶編號 | D3: 服務管道 | E3: 問題類型 | F3: 問題細項 | G3: 優先程度 | H3: 負責人員編號 | I3: 負責團隊 | J3: 案件狀態 | K3: 首次回覆時間 | L3: 結案時間 | M3: 首次回覆分鐘 | N3: 處理時間小時 | O3: 首次回覆上限（分鐘） | P3: 結案上限（小時） | Q3: SLA狀態 | R3: 是否重複來件 | S3: 調查回覆 | T3: 整體滿意度 | U3: 服務月份 | V3: 目前等待小時
A4: TK-2026-0001 | B4: 46113.411 | C4: C0319 | D4: 線上客服 | E4: 登入問題 | F4: 忘記密碼 | G4: 低 | H4: E008 | I4: =VLOOKUP(H4,人員與團隊!$A$4:$D$27,3,FALSE) -> 北區服務 | J4: 已結案 | K4: 46113.575 | L4: 46113.726 | M4: =IF(K4="","",(K4-B4)*1440) -> 236 | N4: =IF(L4="","",(L4-B4)*24) -> 7.5512503 | O4: =VLOOKUP(G4,SLA標準!$A$4:$C$7,2,FALSE) -> 480 | P4: =VLOOKUP(G4,SLA標準!$A$4:$C$7,3,FALSE) -> 48 | Q4: =IF(J4="已結案",IF(AND(M4<=O4,N4<=P4),"達標","逾期"),IF(OR(M4>O4,V4>P4),"逾期","進行中")) -> 達標 | R4: 否 | S4: =IF(T4="","否","是") -> 否 | T4: =IFERROR(VLOOKUP(A4,滿意度調查!$B$4:$D$570,3,FALSE),"") | U4: =TEXT(B4,"yyyy-mm") -> 2026-04 | V4: =IF(J4="已結案",0,(使用說明!$B$7-B4)*24) -> 0
A5: TK-2026-0002 | B5: 46113.432 | C5: C0285 | D5: Email | E5: 系統異常 | F5: 功能操作失敗 | G5: 高 | H5: E006 | I5: =VLOOKUP(H5,人員與團隊!$A$4:$D$27,3,FALSE) -> 北區服務 | J5: 已結案 | K5: 46113.474 | L5: 46113.929 | M5: =IF(K5="","",(K5-B5)*1440) -> 60 | N5: =IF(L5="","",(L5-B5)*24) -> 11.940197 | O5: =VLOOKUP(G5,SLA標準!$A$4:$C$7,2,FALSE) -> 60 | P5: =VLOOKUP(G5,SLA標準!$A$4:$C$7,3,FALSE) -> 8 | Q5: =IF(J5="已結案",IF(AND(M5<=O5,N5<=P5),"達標","逾期"),IF(OR(M5>O5,V5>P5),"逾期","進行中")) -> 逾期 | R5: 否 | S5: =IF(T5="","否","是") -> 否 | T5: =IFERROR(VLOOKUP(A5,滿意度調查!$B$4:$D$570,3,FALSE),"") | U5: =TEXT(B5,"yyyy-mm") -> 2026-04 | V5: =IF(J5="已結案",0,(使用說明!$B$7-B5)*24) -> 0
A6: TK-2026-0003 | B6: 46113.466 | C6: C0178 | D6: 電話 | E6: 登入問題 | F6: 無法完成登入 | G6: 高 | H6: E002 | I6: =VLOOKUP(H6,人員與團隊!$A$4:$D$27,3,FALSE) -> 北區服務 | J6: 已結案 | K6: 46113.479 | L6: 46113.6 | M6: =IF(K6="","",(K6-B6)*1440) -> 19 | N6: =IF(L6="","",(L6-B6)*24) -> 3.2133164 | O6: =VLOOKUP(G6,SLA標準!$A$4:$C$7,2,FALSE) -> 60 | P6: =VLOOKUP(G6,SLA標準!$A$4:$C$7,3,FALSE) -> 8 | Q6: =IF(J6="已結案",IF(AND(M6<=O6,N6<=P6),"達標","逾期"),IF(OR(M6>O6,V6>P6),"逾期","進行中")) -> 達標 | R6: 否 | S6: =IF(T6="","否","是") -> 否 | T6: =IFERROR(VLOOKUP(A6,滿意度調查!$B$4:$D$570,3,FALSE),"") | U6: =TEXT(B6,"yyyy-mm") -> 2026-04 | V6: =IF(J6="已結案",0,(使用說明!$B$7-B6)*24) -> 0
A7: TK-2026-0004 | B7: 46113.624 | C7: C0293 | D7: 電話 | E7: 退換貨 | F7: 換貨進度查詢 | G7: 低 | H7: E005 | I7: =VLOOKUP(H7,人員與團隊!$A$4:$D$27,3,FALSE) -> 北區服務 | J7: 已結案 | K7: 46113.806 | L7: 46114.116 | M7: =IF(K7="","",(K7-B7)*1440) -> 261 | N7: =IF(L7="","",(L7-B7)*24) -> 11.788683 | O7: =VLOOKUP(G7,SLA標準!$A$4:$C$7,2,FALSE) -> 480 | P7: =VLOOKUP(G7,SLA標準!$A$4:$C$7,3,FALSE) -> 48 | Q7: =IF(J7="已結案",IF(AND(M7<=O7,N7<=P7),"達標","逾期"),IF(OR(M7>O7,V7>P7),"逾期","進行中")) -> 達標 | R7: 否 | S7: =IF(T7="","否","是") -> 是 | T7: =IFERROR(VLOOKUP(A7,滿意度調查!$B$4:$D$570,3,FALSE),"") -> 4 | U7: =TEXT(B7,"yyyy-mm") -> 2026-04 | V7: =IF(J7="已結案",0,(使用說明!$B$7-B7)*24) -> 0
A8: TK-2026-0005 | B8: 46113.651 | C8: C0266 | D8: 電話 | E8: 訂單問題 | F8: 優惠未套用 | G8: 高 | H8: E007 | I8: =VLOOKUP(H8,人員與團隊!$A$4:$D$27,3,FALSE) -> 北區服務 | J8: 已結案 | K8: 46113.686 | L8: 46113.954 | M8: =IF(K8="","",(K8-B8)*1440) -> 50 | N8: =IF(L8="","",(L8-B8)*24) -> 7.2577625 | O8: =VLOOKUP(G8,SLA標準!$A$4:$C$7,2,FALSE) -> 60 | P8: =VLOOKUP(G8,SLA標準!$A$4:$C$7,3,FALSE) -> 8 | Q8: =IF(J8="已結案",IF(AND(M8<=O8,N8<=P8),"達標","逾期"),IF(OR(M8>O8,V8>P8),"逾期","進行中")) -> 達標 | R8: 否 | S8: =IF(T8="","否","是") -> 是 | T8: =IFERROR(VLOOKUP(A8,滿意度調查!$B$4:$D$570,3,FALSE),"") -> 5 | U8: =TEXT(B8,"yyyy-mm") -> 2026-04 | V8: =IF(J8="已結案",0,(使用說明!$B$7-B8)*24) -> 0
A9: TK-2026-0006 | B9: 46113.676 | C9: C0251 | D9: 社群 | E9: 訂單問題 | F9: 無法修改訂單 | G9: 一般 | H9: E015 | I9: =VLOOKUP(H9,人員與團隊!$A$4:$D$27,3,FALSE) -> 南區服務 | J9: 已結案 | K9: 46113.8 | L9: 46114.025 | M9: =IF(K9="","",(K9-B9)*1440) -> 179 | N9: =IF(L9="","",(L9-B9)*24) -> 8.3880422 | O9: =VLOOKUP(G9,SLA標準!$A$4:$C$7,2,FALSE) -> 240 | P9: =VLOOKUP(G9,SLA標準!$A$4:$C$7,3,FALSE) -> 24 | Q9: =IF(J9="已結案",IF(AND(M9<=O9,N9<=P9),"達標","逾期"),IF(OR(M9>O9,V9>P9),"逾期","進行中")) -> 達標 | R9: 否 | S9: =IF(T9="","否","是") -> 否 | T9: =IFERROR(VLOOKUP(A9,滿意度調查!$B$4:$D$570,3,FALSE),"") | U9: =TEXT(B9,"yyyy-mm") -> 2026-04 | V9: =IF(J9="已結案",0,(使用說明!$B$7-B9)*24) -> 0
A10: TK-2026-0007 | B10: 46113.735 | C10: C0319 | D10: 電話 | E10: 帳務問題 | F10: 退款尚未入帳 | G10: 低 | H10: E015 | I10: =VLOOKUP(H10,人員與團隊!$A$4:$D$27,3,FALSE) -> 南區服務 | J10: 已結案 | K10: 46113.918 | L10: 46115.566 | M10: =IF(K10="","",(K10-B10)*1440) -> 264 | N10: =IF(L10="","",(L10-B10)*24) -> 43.955066 | O10: =VLOOKUP(G10,SLA標準!$A$4:$C$7,2,FALSE) -> 480 | P10: =VLOOKUP(G10,SLA標準!$A$4:$C$7,3,FALSE) -> 48 | Q10: =IF(J10="已結案",IF(AND(M10<=O10,N10<=P10),"達標","逾期"),IF(OR(M10>O10,V10>P10),"逾期","進行中")) -> 達標 | R10: 否 | S10: =IF(T10="","否","是") -> 是 | T10: =IFERROR(VLOOKUP(A10,滿意度調查!$B$4:$D$570,3,FALSE),"") -> 5 | U10: =TEXT(B10,"yyyy-mm") -> 2026-04 | V10: =IF(J10="已結案",0,(使用說明!$B$7-B10)*24) -> 0
A11: TK-2026-0008 | B11: 46113.761 | C11: C0185 | D11: 線上客服 | E11: 系統異常 | F11: 資料未同步 | G11: 高 | H11: E010 | I11: =VLOOKUP(H11,人員與團隊!$A$4:$D$27,3,FALSE) -> 南區服務 | J11: 已結案 | K11: 46113.771 | L11: 46114.4 | M11: =IF(K11="","",(K11-B11)*1440) -> 14 | N11: =IF(L11="","",(L11-B11)*24) -> 15.333301 | O11: =VLOOKUP(G11,SLA標準!$A$4:$C$7,2,FALSE) -> 60 | P11: =VLOOKUP(G11,SLA標準!$A$4:$C$7,3,FALSE) -> 8 | Q11: =IF(J11="已結案",IF(AND(M11<=O11,N11<=P11),"達標","逾期"),IF(OR(M11>O11,V11>P11),"逾期","進行中")) -> 逾期 | R11: 否 | S11: =IF(T11="","否","是") -> 是 | T11: =IFERROR(VLOOKUP(A11,滿意度調查!$B$4:$D$570,3,FALSE),"") -> 3 | U11: =TEXT(B11,"yyyy-mm") -> 2026-04 | V11: =IF(J11="已結案",0,(使用說明!$B$7-B11)*24) -> 0
A12: TK-2026-0009 | B12: 46113.871 | C12: C0035 | D12: 線上客服 | E12: 訂單問題 | F12: 訂單內容錯誤 | G12: 高 | H12: E021 | I12: =VLOOKUP(H12,人員與團隊!$A$4:$D$27,3,FALSE) -> 線上服務 | J12: 已結案 | K12: 46113.885 | L12: 46114.243 | M12: =IF(K12="","",(K12-B12)*1440) -> 21 | N12: =IF(L12="","",(L12-B12)*24) -> 8.9419889 | O12: =VLOOKUP(G12,SLA標準!$A$4:$C$7,2,FALSE) -> 60 | P12: =VLOOKUP(G12,SLA標準!$A$4:$C$7,3,FALSE) -> 8 | Q12: =IF(J12="已結案",IF(AND(M12<=O12,N12<=P12),"達標","逾期"),IF(OR(M12>O12,V12>P12),"逾期","進行中")) -> 逾期 | R12: 否 | S12: =IF(T12="","否","是") -> 否 | T12: =IFERROR(VLOOKUP(A12,滿意度調查!$B$4:$D$570,3,FALSE),"") | U12: =TEXT(B12,"yyyy-mm") -> 2026-04 | V12: =IF(J12="已結案",0,(使用說明!$B$7-B12)*24) -> 0
A13: TK-2026-0010 | B13: 46114.387 | C13: C0162 | D13: 電話 | E13: 系統異常 | F13: 頁面無法開啟 | G13: 一般 | H13: E015 | I13: =VLOOKUP(H13,人員與團隊!$A$4:$D$27,3,FALSE) -> 南區服務 | J13: 已結案 | K13: 46114.501 | L13: 46115.099 | M13: =IF(K13="","",(K13-B13)*1440) -> 163 | N13: =IF(L13="","",(L13-B13)*24) -> 17.07073 | O13: =VLOOKUP(G13,SLA標準!$A$4:$C$7,2,FALSE) -> 240 | P13: =VLOOKUP(G13,SLA標準!$A$4:$C$7,3,FALSE) -> 24 | Q13: =IF(J13="已結案",IF(AND(M13<=O13,N13<=P13),"達標","逾期"),IF(OR(M13>O13,V13>P13),"逾期","進行中")) -> 達標 | R13: 否 | S13: =IF(T13="","否","是") -> 否 | T13: =IFERROR(VLOOKUP(A13,滿意度調查!$B$4:$D$570,3,FALSE),"") | U13: =TEXT(B13,"yyyy-mm") -> 2026-04 | V13: =IF(J13="已結案",0,(使用說明!$B$7-B13)*24) -> 0
A14: TK-2026-0011 | B14: 46114.556 | C14: C0153 | D14: Email | E14: 帳務問題 | F14: 退款尚未入帳 | G14: 一般 | H14: E002 | I14: =VLOOKUP(H14,人員與團隊!$A$4:$D$27,3,FALSE) -> 北區服務 | J14: 已結案 | K14: 46114.815 | L14: 46115.191 | M14: =IF(K14="","",(K14-B14)*1440) -> 373 | N14: =IF(L14="","",(L14-B14)*24) -> 15.243862 | O14: =VLOOKUP(G14,SLA標準!$A$4:$C$7,2,FALSE) -> 240 | P14: =VLOOKUP(G14,SLA標準!$A$4:$C$7,3,FALSE) -> 24 | Q14: =IF(J14="已結案",IF(AND(M14<=O14,N14<=P14),"達標","逾期"),IF(OR(M14>O14,V14>P14),"逾期","進行中")) -> 逾期 | R14: 否 | S14: =IF(T14="","否","是") -> 是 | T14: =IFERROR(VLOOKUP(A14,滿意度調查!$B$4:$D$570,3,FALSE),"") -> 3 | U14: =TEXT(B14,"yyyy-mm") -> 2026-04 | V14: =IF(J14="已結案",0,(使用說明!$B$7-B14)*24) -> 0
A15: TK-2026-0012 | B15: 46114.739 | C15: C0074 | D15: 電話 | E15: 系統異常 | F15: 資料未同步 | G15: 一般 | H15: E011 | I15: =VLOOKUP(H15,人員與團隊!$A$4:$D$27,3,FALSE) -> 南區服務 | J15: 已結案 | K15: 46114.786 | L15: 46115.57 | M15: =IF(K15="","",(K15-B15)*1440) -> 68 | N15: =IF(L15="","",(L15-B15)*24) -> 19.956402 | O15: =VLOOKUP(G15,SLA標準!$A$4:$C$7,2,FALSE) -> 240 | P15: =VLOOKUP(G15,SLA標準!$A$4:$C$7,3,FALSE) -> 24 | Q15: =IF(J15="已結案",IF(AND(M15<=O15,N15<=P15),"達標","逾期"),IF(OR(M15>O15,V15>P15),"逾期","進行中")) -> 達標 | R15: 是 | S15: =IF(T15="","否","是") -> 是 | T15: =IFERROR(VLOOKUP(A15,滿意度調查!$B$4:$D$570,3,FALSE),"") -> 4 | U15: =TEXT(B15,"yyyy-mm") -> 2026-04 | V15: =IF(J15="已結案",0,(使用說明!$B$7-B15)*24) -> 0
... A18: TK-2026-0015 | B18: 46115.608 | C18: C0082 | D18: 電話 | E18: 退換貨 | F18: 退貨運費爭議 | G18: 一般 | H18: E008 | I18: =VLOOKUP(H18,人員與團隊!$A$4:$D$27,3,FALSE) -> 北區服務 | J18: 已結案 | K18: 46115.675 | L18: 46116.173 | M18: =IF(K18="","",(K18-B18)*1440) -> 96 | N18: =IF(L18="","",(L18-B18)*24) -> 13.547541 | O18: =VLOOKUP(G18,SLA標準!$A$4:$C$7,2,FALSE) -> 240 | P18: =VLOOKUP(G18,SLA標準!$A$4:$C$7,3,FALSE) -> 24 | Q18: =IF(J18="已結案",IF(AND(M18<=O18,N18<=P18),"達標","逾期"),IF(OR(M18>O18,V18>P18),"逾期","進行中")) -> 達標 | R18: 否 | S18: =IF(T18="","否","是") -> 是 | T18: =IFERROR(VLOOKUP(A18,滿意度調查!$B$4:$D$570,3,FALSE),"") -> 5 | U18: =TEXT(B18,"yyyy-mm") -> 2026-04 | V18: =IF(J18="已結案",0,(使用說明!$B$7-B18)*24) -> 0
A19: TK-2026-0016 | B19: 46115.66 | C19: C0185 | D19: 電話 | E19: 訂單問題 | F19: 訂單內容錯誤 | G19: 低 | H19: E014 | I19: =VLOOKUP(H19,人員與團隊!$A$4:$D$27,3,FALSE) -> 南區服務 | J19: 等待客戶 | K19: 46115.816 | M19: =IF(K19="","",(K19-B19)*1440) -> 225 | N19: =IF(L19="","",(L19-B19)*24) | O19: =VLOOKUP(G19,SLA標準!$A$4:$C$7,2,FALSE) -> 480 | P19: =VLOOKUP(G19,SLA標準!$A$4:$C$7,3,FALSE) -> 48 | Q19: =IF(J19="已結案",IF(AND(M19<=O19,N19<=P19),"達標","逾期"),IF(OR(M19>O19,V19>P19),"逾期","進行中")) -> 逾期 | R19: 否 | S19: =IF(T19="","否","是") -> 否 | T19: =IFERROR(VLOOKUP(A19,滿意度調查!$B$4:$D$570,3,FALSE),"") | U19: =TEXT(B19,"yyyy-mm") -> 2026-04 | V19: =IF(J19="已結案",0,(使用說明!$B$7-B19)*24) -> 2129.1667
A20: TK-2026-0017 | B20: 46115.767 | C20: C0114 | D20: 電話 | E20: 帳務問題 | F20: 發票資料錯誤 | G20: 一般 | H20: E013 | I20: =VLOOKUP(H20,人員與團隊!$A$4:$D$27,3,FALSE) -> 南區服務 | J20: 已結案 | K20: 46115.854 | L20: 46116.47 | M20: =IF(K20="","",(K20-B20)*1440) -> 125 | N20: =IF(L20="","",(L20-B20)*24) -> 16.869447 | O20: =VLOOKUP(G20,SLA標準!$A$4:$C$7,2,FALSE) -> 240 | P20: =VLOOKUP(G20,SLA標準!$A$4:$C$7,3,FALSE) -> 24 | Q20: =IF(J20="已結案",IF(AND(M20<=O20,N20<=P20),"達標","逾期"),IF(OR(M20>O20,V20>P20),"逾期","進行中")) -> 達標 | R20: 否 | S20: =IF(T20="","否","是") -> 是 | T20: =IFERROR(VLOOKUP(A20,滿意度調查!$B$4:$D$570,3,FALSE),"") -> 5 | U20: =TEXT(B20,"yyyy-mm") -> 2026-04 | V20: =IF(J20="已結案",0,(使用說明!$B$7-B20)*24) -> 0
A21: TK-2026-0018 | B21: 46115.838 | C21: C0253 | D21: 電話 | E21: 帳務問題 | F21: 付款失敗 | G21: 一般 | H21: E005 | I21: =VLOOKUP(H21,人員與團隊!$A$4:$D$27,3,FALSE) -> 北區服務 | J21: 已結案 | K21: 46115.947 | L21: 46117.772 | M21: =IF(K21="","",(K21-B21)*1440) -> 158 | N21: =IF(L21="","",(L21-B21)*24) -> 46.429889 | O21: =VLOOKUP(G21,SLA標準!$A$4:$C$7,2,FALSE) -> 240 | P21: =VLOOKUP(G21,SLA標準!$A$4:$C$7,3,FALSE) -> 24 | Q21: =IF(J21="已結案",IF(AND(M21<=O21,N21<=P21),"達標","逾期"),IF(OR(M21>O21,V21>P21),"逾期","進行中")) -> 逾期 | R21: 否 | S21: =IF(T21="","否","是") -> 是 | T21: =IFERROR(VLOOKUP(A21,滿意度調查!$B$4:$D$570,3,FALSE),"") -> 3 | U21: =TEXT(B21,"yyyy-mm") -> 2026-04 | V21: =IF(J21="已結案",0,(使用說明!$B$7-B21)*24) -> 0
A22: TK-2026-0019 | B22: 46115.869 | C22: C0097 | D22: 社群 | E22: 系統異常 | F22: 功能操作失敗 | G22: 高 | H22: E024 | I22: =VLOOKUP(H22,人員與團隊!$A$4:$D$27,3,FALSE) -> 線上服務 | J22: 已結案 | K22: 46115.908 | L22: 46116.352 | M22: =IF(K22="","",(K22-B22)*1440) -> 55 | N22: =IF(L22="","",(L22-B22)*24) -> 11.572657 | O22: =VLOOKUP(G22,SLA標準!$A$4:$C$7,2,FALSE) -> 60 | P22: =VLOOKUP(G22,SLA標準!$A$4:$C$7,3,FALSE) -> 8 | Q22: =IF(J22="已結案",IF(AND(M22<=O22,N22<=P22),"達標","逾期"),IF(OR(M22>O22,V22>P22),"逾期","進行中")) -> 逾期 | R22: 否 | S22: =IF(T22="","否","是") -> 是 | T22: =IFERROR(VLOOKUP(A22,滿意度調查!$B$4:$D$570,3,FALSE),"") -> 3 | U22: =TEXT(B22,"yyyy-mm") -> 2026-04 | V22: =IF(J22="已結案",0,(使用說明!$B$7-B22)*24) -> 0
A23: TK-2026-0020 | B23: 46116.373 | C23: C0228 | D23: 線上客服 | E23: 系統異常 | F23: 頁面無法開啟 | G23: 高 | H23: E016 | I23: =VLOOKUP(H23,人員與團隊!$A$4:$D$27,3,FALSE) -> 南區服務 | J23: 已結案 | K23: 46116.381 | L23: 46116.688 | M23: =IF(K23="","",(K23-B23)*1440) -> 12 | N23: =IF(L23="","",(L23-B23)*24) -> 7.5723136 | O23: =VLOOKUP(G23,SLA標準!$A$4:$C$7,2,FALSE) -> 60 | P23: =VLOOKUP(G23,SLA標準!$A$4:$C$7,3,FALSE) -> 8 | Q23: =IF(J23="已結案",IF(AND(M23<=O23,N23<=P23),"達標","逾期"),IF(OR(M23>O23,V23>P23),"逾期","進行中")) -> 達標 | R23: 否 | S23: =IF(T23="","否","是") -> 否 | T23: =IFERROR(VLOOKUP(A23,滿意度調查!$B$4:$D$570,3,FALSE),"") | U23: =TEXT(B23,"yyyy-mm") -> 2026-04 | V23: =IF(J23="已結案",0,(使用說明!$B$7-B23)*24) -> 0
A24: TK-2026-0021 | B24: 46116.394 | C24: C0191 | D24: 社群 | E24: 配送問題 | F24: 商品尚未到貨 | G24: 一般 | H24: E013 | I24: =VLOOKUP(H24,人員與團隊!$A$4:$D$27,3,FALSE) -> 南區服務 | J24: 已結案 | K24: 46116.578 | L24: 46117.199 | M24: =IF(K24="","",(K24-B24)*1440) -> 264 | N24: =IF(L24="","",(L24-B24)*24) -> 19.312285 | O24: =VLOOKUP(G24,SLA標準!$A$4:$C$7,2,FALSE) -> 240 | P24: =VLOOKUP(G24,SLA標準!$A$4:$C$7,3,FALSE) -> 24 | Q24: =IF(J24="已結案",IF(AND(M24<=O24,N24<=P24),"達標","逾期"),IF(OR(M24>O24,V24>P24),"逾期","進行中")) -> 逾期 | R24: 否 | S24: =IF(T24="","否","是") -> 是 | T24: =IFERROR(VLOOKUP(A24,滿意度調查!$B$4:$D$570,3,FALSE),"") -> 4 | U24: =TEXT(B24,"yyyy-mm") -> 2026-04 | V24: =IF(J24="已結案",0,(使用說明!$B$7-B24)*24) -> 0
A25: TK-2026-0022 | B25: 46116.53 | C25: C0179 | D25: 電話 | E25: 帳務問題 | F25: 發票資料錯誤 | G25: 一般 | H25: E013 | I25: =VLOOKUP(H25,人員與團隊!$A$4:$D$27,3,FALSE) -> 南區服務 | J25: 已結案 | K25: 46116.612 | L25: 46117.813 | M25: =IF(K25="","",(K25-B25)*1440) -> 118 | N25: =IF(L25="","",(L25-B25)*24) -> 30.795754 | O25: =VLOOKUP(G25,SLA標準!$A$4:$C$7,2,FALSE) -> 240 | P25: =VLOOKUP(G25,SLA標準!$A$4:$C$7,3,FALSE) -> 24 | Q25: =IF(J25="已結案",IF(AND(M25<=O25,N25<=P25),"達標","逾期"),IF(OR(M25>O25,V25>P25),"逾期","進行中")) -> 逾期 | R25: 是 | S25: =IF(T25="","否","是") -> 是 | T25: =IFERROR(VLOOKUP(A25,滿意度調查!$B$4:$D$570,3,FALSE),"") -> 2 | U25: =TEXT(B25,"yyyy-mm") -> 2026-04 | V25: =IF(J25="已結案",0,(使用說明!$B$7-B25)*24) -> 0
A26: TK-2026-0023 | B26: 46116.705 | C26: C0095 | D26: 社群 | E26: 退換貨 | F26: 換貨進度查詢 | G26: 一般 | H26: E014 | I26: =VLOOKUP(H26,人員與團隊!$A$4:$D$27,3,FALSE) -> 南區服務 | J26: 已結案 | K26: 46116.822 | L26: 46117.543 | M26: =IF(K26="","",(K26-B26)*1440) -> 169 | N26: =IF(L26="","",(L26-B26)*24) -> 20.119471 | O26: =VLOOKUP(G26,SLA標準!$A$4:$C$7,2,FALSE) -> 240 | P26: =VLOOKUP(G26,SLA標準!$A$4:$C$7,3,FALSE) -> 24 | Q26: =IF(J26="已結案",IF(AND(M26<=O26,N26<=P26),"達標","逾期"),IF(OR(M26>O26,V26>P26),"逾期","進行中")) -> 達標 | R26: 是 | S26: =IF(T26="","否","是") -> 是 | T26: =IFERROR(VLOOKUP(A26,滿意度調查!$B$4:$D$570,3,FALSE),"") -> 4 | U26: =TEXT(B26,"yyyy-mm") -> 2026-04 | V26: =IF(J26="已結案",0,(使用說明!$B$7-B26)*24) -> 0
A27: TK-2026-0024 | B27: 46116.803 | C27: C0212 | D27: 社群 | E27: 退換貨 | F27: 退貨運費爭議 | G27: 高 | H27: E014 | I27: =VLOOKUP(H27,人員與團隊!$A$4:$D$27,3,FALSE) -> 南區服務 | J27: 已結案 | K27: 46116.861 | L27: 46117.395 | M27: =IF(K27="","",(K27-B27)*1440) -> 83 | N27: =IF(L27="","",(L27-B27)*24) -> 14.186221 | O27: =VLOOKUP(G27,SLA標準!$A$4:$C$7,2,FALSE) -> 60 | P27: =VLOOKUP(G27,SLA標準!$A$4:$C$7,3,FALSE) -> 8 | Q27: =IF(J27="已結案",IF(AND(M27<=O27,N27<=P27),"達標","逾期"),IF(OR(M27>O27,V27>P27),"逾期","進行中")) -> 逾期 | R27: 否 | S27: =IF(T27="","否","是") -> 否 | T27: =IFERROR(VLOOKUP(A27,滿意度調查!$B$4:$D$570,3,FALSE),"") | U27: =TEXT(B27,"yyyy-mm") -> 2026-04 | V27: =IF(J27="已結案",0,(使用說明!$B$7-B27)*24) -> 0
A28: TK-2026-0025 | B28: 46116.83 | C28: C0068 | D28: 社群 | E28: 訂單問題 | F28: 訂單狀態未更新 | G28: 一般 | H28: E013 | I28: =VLOOKUP(H28,人員與團隊!$A$4:$D$27,3,FALSE) -> 南區服務 | J28: 已結案 | K28: 46116.981 | L28: 46117.106 | M28: =IF(K28="","",(K28-B28)*1440) -> 218 | N28: =IF(L28="","",(L28-B28)*24) -> 6.6365108 | O28: =VLOOKUP(G28,SLA標準!$A$4:$C$7,2,FALSE) -> 240 | P28: =VLOOKUP(G28,SLA標準!$A$4:$C$7,3,FALSE) -> 24 | Q28: =IF(J28="已結案",IF(AND(M28<=O28,N28<=P28),"達標","逾期"),IF(OR(M28>O28,V28>P28),"逾期","進行中")) -> 達標 | R28: 否 | S28: =IF(T28="","否","是") -> 是 | T28: =IFERROR(VLOOKUP(A28,滿意度調查!$B$4:$D$570,3,FALSE),"") -> 5 | U28: =TEXT(B28,"yyyy-mm") -> 2026-04 | V28: =IF(J28="已結案",0,(使用說明!$B$7-B28)*24) -> 0
A29: TK-2026-0026 | B29: 46117.401 | C29: C0287 | D29: Email | E29: 配送問題 | F29: 物流狀態未更新 | G29: 一般 | H29: E002 | I29: =VLOOKUP(H29,人員與團隊!$A$4:$D$27,3,FALSE) -> 北區服務 | J29: 已結案 | K29: 46117.528 | L29: 46118.331 | M29: =IF(K29="","",(K29-B29)*1440) -> 184 | N29: =IF(L29="","",(L29-B29)*24) -> 22.327015 | O29: =VLOOKUP(G29,SLA標準!$A$4:$C$7,2,FALSE) -> 240 | P29: =VLOOKUP(G29,SLA標準!$A$4:$C$7,3,FALSE) -> 24 | Q29: =IF(J29="已結案",IF(AND(M29<=O29,N29<=P29),"達標","逾期"),IF(OR(M29>O29,V29>P29),"逾期","進行中")) -> 達標 | R29: 否 | S29: =IF(T29="","否","是") -> 否 | T29: =IFERROR(VLOOKUP(A29,滿意度調查!$B$4:$D$570,3,FALSE),"") | U29: =TEXT(B29,"yyyy-mm") -> 2026-04 | V29: =IF(J29="已結案",0,(使用說明!$B$7-B29)*24) -> 0
A30: TK-2026-0027 | B30: 46117.419 | C30: C0140 | D30: 線上客服 | E30: 配送問題 | F30: 配送時間異常 | G30: 一般 | H30: E020 | I30: =VLOOKUP(H30,人員與團隊!$A$4:$D$27,3,FALSE) -> 線上服務 | J30: 已結案 | K30: 46117.469 | L30: 46118.274 | M30: =IF(K30="","",(K30-B30)*1440) -> 72 | N30: =IF(L30="","",(L30-B30)*24) -> 20.527661 | O30: =VLOOKUP(G30,SLA標準!$A$4:$C$7,2,FALSE) -> 240 | P30: =VLOOKUP(G30,SLA標準!$A$4:$C$7,3,FALSE) -> 24 | Q30: =IF(J30="已結案",IF(AND(M30<=O30,N30<=P30),"達標","逾期"),IF(OR(M30>O30,V30>P30),"逾期","進行中")) -> 達標 | R30: 否 | S30: =IF(T30="","否","是") -> 是 | T30: =IFERROR(VLOOKUP(A30,滿意度調查!$B$4:$D$570,3,FALSE),"") -> 5 | U30: =TEXT(B30,"yyyy-mm") -> 2026-04 | V30: =IF(J30="已結案",0,(使用說明!$B$7-B30)*24) -> 0
A31: TK-2026-0028 | B31: 46117.52 | C31: C0275 | D31: 線上客服 | E31: 訂單問題 | F31: 優惠未套用 | G31: 一般 | H31: E013 | I31: =VLOOKUP(H31,人員與團隊!$A$4:$D$27,3,FALSE) -> 南區服務 | J31: 已結案 | K31: 46117.618 | L31: 46118.307 | M31: =IF(K31="","",(K31-B31)*1440) -> 141 | N31: =IF(L31="","",(L31-B31)*24) -> 18.890183 | O31: =VLOOKUP(G31,SLA標準!$A$4:$C$7,2,FALSE) -> 240 | P31: =VLOOKUP(G31,SLA標準!$A$4:$C$7,3,FALSE) -> 24 | Q31: =IF(J31="已結案",IF(AND(M31<=O31,N31<=P31),"達標","逾期"),IF(OR(M31>O31,V31>P31),"逾期","進行中")) -> 達標 | R31: 否 | S31: =IF(T31="","否","是") -> 是 | T31: =IFERROR(VLOOKUP(A31,滿意度調查!$B$4:$D$570,3,FALSE),"") -> 5 | U31: =TEXT(B31,"yyyy-mm") -> 2026-04 | V31: =IF(J31="已結案",0,(使用說明!$B$7-B31)*24) -> 0
... A50: TK-2026-0047 | B50: 46119.649 | C50: C0093 | D50: 電話 | E50: 退換貨 | F50: 換貨進度查詢 | G50: 緊急 | H50: E010 | I50: =VLOOKUP(H50,人員與團隊!$A$4:$D$27,3,FALSE) -> 南區服務 | J50: 已結案 | K50: 46119.655 | L50: 46120.096 | M50: =IF(K50="","",(K50-B50)*1440) -> 9 | N50: =IF(L50="","",(L50-B50)*24) -> 10.727381 | O50: =VLOOKUP(G50,SLA標準!$A$4:$C$7,2,FALSE) -> 30 | P50: =VLOOKUP(G50,SLA標準!$A$4:$C$7,3,FALSE) -> 4 | Q50: =IF(J50="已結案",IF(AND(M50<=O50,N50<=P50),"達標","逾期"),IF(OR(M50>O50,V50>P50),"逾期","進行中")) -> 逾期 | R50: 否 | S50: =IF(T50="","否","是") -> 是 | T50: =IFERROR(VLOOKUP(A50,滿意度調查!$B$4:$D$570,3,FALSE),"") -> 2 | U50: =TEXT(B50,"yyyy-mm") -> 2026-04 | V50: =IF(J50="已結案",0,(使用說明!$B$7-B50)*24) -> 0
A51: TK-2026-0048 | B51: 46119.775 | C51: C0098 | D51: Email | E51: 帳務問題 | F51: 發票資料錯誤 | G51: 緊急 | H51: E013 | I51: =VLOOKUP(H51,人員與團隊!$A$4:$D$27,3,FALSE) -> 南區服務 | J51: 處理中 | K51: 46119.808 | M51: =IF(K51="","",(K51-B51)*1440) -> 47 | N51: =IF(L51="","",(L51-B51)*24) | O51: =VLOOKUP(G51,SLA標準!$A$4:$C$7,2,FALSE) -> 30 | P51: =VLOOKUP(G51,SLA標準!$A$4:$C$7,3,FALSE) -> 4 | Q51: =IF(J51="已結案",IF(AND(M51<=O51,N51<=P51),"達標","逾期"),IF(OR(M51>O51,V51>P51),"逾期","進行中")) -> 逾期 | R51: 否 | S51: =IF(T51="","否","是") -> 否 | T51: =IFERROR(VLOOKUP(A51,滿意度調查!$B$4:$D$570,3,FALSE),"") | U51: =TEXT(B51,"yyyy-mm") -> 2026-04 | V51: =IF(J51="已結案",0,(使用說明!$B$7-B51)*24) -> 2030.4
A52: TK-2026-0049 | B52: 46119.808 | C52: C0035 | D52: 電話 | E52: 帳務問題 | F52: 重複扣款 | G52: 一般 | H52: E014 | I52: =VLOOKUP(H52,人員與團隊!$A$4:$D$27,3,FALSE) -> 南區服務 | J52: 已結案 | K52: 46119.954 | L52: 46121.219 | M52: =IF(K52="","",(K52-B52)*1440) -> 210 | N52: =IF(L52="","",(L52-B52)*24) -> 33.848431 | O52: =VLOOKUP(G52,SLA標準!$A$4:$C$7,2,FALSE) -> 240 | P52: =VLOOKUP(G52,SLA標準!$A$4:$C$7,3,FALSE) -> 24 | Q52: =IF(J52="已結案",IF(AND(M52<=O52,N52<=P52),"達標","逾期"),IF(OR(M52>O52,V52>P52),"逾期","進行中")) -> 逾期 | R52: 是 | S52: =IF(T52="","否","是") -> 否 | T52: =IFERROR(VLOOKUP(A52,滿意度調查!$B$4:$D$570,3,FALSE),"") | U52: =TEXT(B52,"yyyy-mm") -> 2026-04 | V52: =IF(J52="已結案",0,(使用說明!$B$7-B52)*24) -> 0
A53: TK-2026-0050 | B53: 46121.381 | C53: C0182 | D53: Email | E53: 登入問題 | F53: 無法完成登入 | G53: 一般 | H53: E009 | I53: =VLOOKUP(H53,人員與團隊!$A$4:$D$27,3,FALSE) -> 南區服務 | J53: 已結案 | K53: 46121.565 | L53: 46121.592 | M53: =IF(K53="","",(K53-B53)*1440) -> 266 | N53: =IF(L53="","",(L53-B53)*24) -> 5.0691944 | O53: =VLOOKUP(G53,SLA標準!$A$4:$C$7,2,FALSE) -> 240 | P53: =VLOOKUP(G53,SLA標準!$A$4:$C$7,3,FALSE) -> 24 | Q53: =IF(J53="已結案",IF(AND(M53<=O53,N53<=P53),"達標","逾期"),IF(OR(M53>O53,V53>P53),"逾期","進行中")) -> 逾期 | R53: 否 | S53: =IF(T53="","否","是") -> 是 | T53: =IFERROR(VLOOKUP(A53,滿意度調查!$B$4:$D$570,3,FALSE),"") -> 3 | U53: =TEXT(B53,"yyyy-mm") -> 2026-04 | V53: =IF(J53="已結案",0,(使用說明!$B$7-B53)*24) -> 0
A54: TK-2026-0051 | B54: 46121.471 | C54: C0099 | D54: 線上客服 | E54: 系統異常 | F54: 資料未同步 | G54: 高 | H54: E024 | I54: =VLOOKUP(H54,人員與團隊!$A$4:$D$27,3,FALSE) -> 線上服務 | J54: 已結案 | K54: 46121.484 | L54: 46121.69 | M54: =IF(K54="","",(K54-B54)*1440) -> 19 | N54: =IF(L54="","",(L54-B54)*24) -> 5.2480308 | O54: =VLOOKUP(G54,SLA標準!$A$4:$C$7,2,FALSE) -> 60 | P54: =VLOOKUP(G54,SLA標準!$A$4:$C$7,3,FALSE) -> 8 | Q54: =IF(J54="已結案",IF(AND(M54<=O54,N54<=P54),"達標","逾期"),IF(OR(M54>O54,V54>P54),"逾期","進行中")) -> 達標 | R54: 否 | S54: =IF(T54="","否","是") -> 否 | T54: =IFERROR(VLOOKUP(A54,滿意度調查!$B$4:$D$570,3,FALSE),"") | U54: =TEXT(B54,"yyyy-mm") -> 2026-04 | V54: =IF(J54="已結案",0,(使用說明!$B$7-B54)*24) -> 0
A55: TK-2026-0052 | B55: 46121.512 | C55: C0014 | D55: Email | E55: 配送問題 | F55: 商品尚未到貨 | G55: 一般 | H55: E003 | I55: =VLOOKUP(H55,人員與團隊!$A$4:$D$27,3,FALSE) -> 北區服務 | J55: 已結案 | K55: 46121.71 | L55: 46122.518 | M55: =IF(K55="","",(K55-B55)*1440) -> 284 | N55: =IF(L55="","",(L55-B55)*24) -> 24.137386 | O55: =VLOOKUP(G55,SLA標準!$A$4:$C$7,2,FALSE) -> 240 | P55: =VLOOKUP(G55,SLA標準!$A$4:$C$7,3,FALSE) -> 24 | Q55: =IF(J55="已結案",IF(AND(M55<=O55,N55<=P55),"達標","逾期"),IF(OR(M55>O55,V55>P55),"逾期","進行中")) -> 逾期 | R55: 否 | S55: =IF(T55="","否","是") -> 否 | T55: =IFERROR(VLOOKUP(A55,滿意度調查!$B$4:$D$570,3,FALSE),"") | U55: =TEXT(B55,"yyyy-mm") -> 2026-04 | V55: =IF(J55="已結案",0,(使用說明!$B$7-B55)*24) -> 0
A56: TK-2026-0053 | B56: 46121.588 | C56: C0248 | D56: 電話 | E56: 登入問題 | F56: 無法完成登入 | G56: 高 | H56: E002 | I56: =VLOOKUP(H56,人員與團隊!$A$4:$D$27,3,FALSE) -> 北區服務 | J56: 已結案 | K56: 46121.612 | L56: 46121.797 | M56: =IF(K56="","",(K56-B56)*1440) -> 34 | N56: =IF(L56="","",(L56-B56)*24) -> 5.0130878 | O56: =VLOOKUP(G56,SLA標準!$A$4:$C$7,2,FALSE) -> 60 | P56: =VLOOKUP(G56,SLA標準!$A$4:$C$7,3,FALSE) -> 8 | Q56: =IF(J56="已結案",IF(AND(M56<=O56,N56<=P56),"達標","逾期"),IF(OR(M56>O56,V56>P56),"逾期","進行中")) -> 達標 | R56: 是 | S56: =IF(T56="","否","是") -> 否 | T56: =IFERROR(VLOOKUP(A56,滿意度調查!$B$4:$D$570,3,FALSE),"") | U56: =TEXT(B56,"yyyy-mm") -> 2026-04 | V56: =IF(J56="已結案",0,(使用說明!$B$7-B56)*24) -> 0
A57: TK-2026-0054 | B57: 46121.653 | C57: C0008 | D57: Email | E57: 系統異常 | F57: 頁面無法開啟 | G57: 高 | H57: E017 | I57: =VLOOKUP(H57,人員與團隊!$A$4:$D$27,3,FALSE) -> 線上服務 | J57: 已結案 | K57: 46121.706 | L57: 46121.853 | M57: =IF(K57="","",(K57-B57)*1440) -> 76 | N57: =IF(L57="","",(L57-B57)*24) -> 4.8081428 | O57: =VLOOKUP(G57,SLA標準!$A$4:$C$7,2,FALSE) -> 60 | P57: =VLOOKUP(G57,SLA標準!$A$4:$C$7,3,FALSE) -> 8 | Q57: =IF(J57="已結案",IF(AND(M57<=O57,N57<=P57),"達標","逾期"),IF(OR(M57>O57,V57>P57),"逾期","進行中")) -> 逾期 | R57: 否 | S57: =IF(T57="","否","是") -> 是 | T57: =IFERROR(VLOOKUP(A57,滿意度調查!$B$4:$D$570,3,FALSE),"") -> 3 | U57: =TEXT(B57,"yyyy-mm") -> 2026-04 | V57: =IF(J57="已結案",0,(使用說明!$B$7-B57)*24) -> 0
A58: TK-2026-0055 | B58: 46121.826 | C58: C0209 | D58: 線上客服 | E58: 系統異常 | F58: 系統反應緩慢 | G58: 緊急 | H58: E012 | I58: =VLOOKUP(H58,人員與團隊!$A$4:$D$27,3,FALSE) -> 南區服務 | J58: 已結案 | K58: 46121.838 | L58: 46122.168 | M58: =IF(K58="","",(K58-B58)*1440) -> 17 | N58: =IF(L58="","",(L58-B58)*24) -> 8.226275 | O58: =VLOOKUP(G58,SLA標準!$A$4:$C$7,2,FALSE) -> 30 | P58: =VLOOKUP(G58,SLA標準!$A$4:$C$7,3,FALSE) -> 4 | Q58: =IF(J58="已結案",IF(AND(M58<=O58,N58<=P58),"達標","逾期"),IF(OR(M58>O58,V58>P58),"逾期","進行中")) -> 逾期 | R58: 否 | S58: =IF(T58="","否","是") -> 否 | T58: =IFERROR(VLOOKUP(A58,滿意度調查!$B$4:$D$570,3,FALSE),"") | U58: =TEXT(B58,"yyyy-mm") -> 2026-04 | V58: =IF(J58="已結案",0,(使用說明!$B$7-B58)*24) -> 0
A59: TK-2026-0056 | B59: 46121.826 | C59: C0005 | D59: 線上客服 | E59: 帳務問題 | F59: 重複扣款 | G59: 一般 | H59: E024 | I59: =VLOOKUP(H59,人員與團隊!$A$4:$D$27,3,FALSE) -> 線上服務 | J59: 已結案 | K59: 46121.934 | L59: 46122.794 | M59: =IF(K59="","",(K59-B59)*1440) -> 155 | N59: =IF(L59="","",(L59-B59)*24) -> 23.224191 | O59: =VLOOKUP(G59,SLA標準!$A$4:$C$7,2,FALSE) -> 240 | P59: =VLOOKUP(G59,SLA標準!$A$4:$C$7,3,FALSE) -> 24 | Q59: =IF(J59="已結案",IF(AND(M59<=O59,N59<=P59),"達標","逾期"),IF(OR(M59>O59,V59>P59),"逾期","進行中")) -> 達標 | R59: 否 | S59: =IF(T59="","否","是") -> 是 | T59: =IFERROR(VLOOKUP(A59,滿意度調查!$B$4:$D$570,3,FALSE),"") -> 5 | U59: =TEXT(B59,"yyyy-mm") -> 2026-04 | V59: =IF(J59="已結案",0,(使用說明!$B$7-B59)*24) -> 0
A60: TK-2026-0057 | B60: 46122.456 | C60: C0002 | D60: 電話 | E60: 登入問題 | F60: 帳號被鎖定 | G60: 一般 | H60: E016 | I60: =VLOOKUP(H60,人員與團隊!$A$4:$D$27,3,FALSE) -> 南區服務 | J60: 已結案 | K60: 46122.567 | L60: 46122.759 | M60: =IF(K60="","",(K60-B60)*1440) -> 159 | N60: =IF(L60="","",(L60-B60)*24) -> 7.2743833 | O60: =VLOOKUP(G60,SLA標準!$A$4:$C$7,2,FALSE) -> 240 | P60: =VLOOKUP(G60,SLA標準!$A$4:$C$7,3,FALSE) -> 24 | Q60: =IF(J60="已結案",IF(AND(M60<=O60,N60<=P60),"達標","逾期"),IF(OR(M60>O60,V60>P60),"逾期","進行中")) -> 達標 | R60: 否 | S60: =IF(T60="","否","是") -> 是 | T60: =IFERROR(VLOOKUP(A60,滿意度調查!$B$4:$D$570,3,FALSE),"") -> 5 | U60: =TEXT(B60,"yyyy-mm") -> 2026-04 | V60: =IF(J60="已結案",0,(使用說明!$B$7-B60)*24) -> 0
...

Sheet 人員與團隊
A1: 客服人員與團隊 | B1: 客服人員與團隊 | C1: 客服人員與團隊 | D1: 客服人員與團隊 | E1: 客服人員與團隊 | F1: 客服人員與團隊 | G1: 客服人員與團隊 | H1: 客服人員與團隊
A2: 人員、團隊與建議工作量主檔；所有姓名均為模擬資料。 | B2: 人員、團隊與建議工作量主檔；所有姓名均為模擬資料。 | C2: 人員、團隊與建議工作量主檔；所有姓名均為模擬資料。 | D2: 人員、團隊與建議工作量主檔；所有姓名均為模擬資料。 | E2: 人員、團隊與建議工作量主檔；所有姓名均為模擬資料。 | F2: 人員、團隊與建議工作量主檔；所有姓名均為模擬資料。 | G2: 人員、團隊與建議工作量主檔；所有姓名均為模擬資料。 | H2: 人員、團隊與建議工作量主檔；所有姓名均為模擬資料。
A3: 人員編號 | B3: 人員姓名 | C3: 所屬團隊 | D3: 服務區域 | E3: 擅長問題類型 | F3: 每日建議案件量 | G3: 人員狀態 | H3: 備註
A4: E001 | B4: 陳怡君 | C4: 北區服務 | D4: 北區 | E4: 帳務問題 | F4: 14 | G4: 在職
A5: E002 | B5: 林柏宇 | C5: 北區服務 | D5: 北區 | E5: 登入問題 | F5: 14 | G5: 請假 | H5: 2026 年 6 月排班暫停
A6: E003 | B6: 張雅雯 | C6: 北區服務 | D6: 北區 | E6: 訂單問題 | F6: 14 | G6: 在職
A7: E004 | B7: 王俊豪 | C7: 北區服務 | D7: 北區 | E7: 配送問題 | F7: 14 | G7: 在職
A8: E005 | B8: 李欣怡 | C8: 北區服務 | D8: 北區 | E8: 退換貨 | F8: 14 | G8: 在職
A9: E006 | B9: 黃冠廷 | C9: 北區服務 | D9: 北區 | E9: 系統異常 | F9: 14 | G9: 請假 | H9: 2026 年 6 月排班暫停
A10: E007 | B10: 吳佩珊 | C10: 北區服務 | D10: 北區 | E10: 帳務問題 | F10: 14 | G10: 在職
A11: E008 | B11: 劉家豪 | C11: 北區服務 | D11: 北區 | E11: 登入問題 | F11: 14 | G11: 在職
A12: E009 | B12: 蔡佳穎 | C12: 南區服務 | D12: 南區 | E12: 訂單問題 | F12: 14 | G12: 在職
A13: E010 | B13: 楊承恩 | C13: 南區服務 | D13: 南區 | E13: 配送問題 | F13: 14 | G13: 在職
A14: E011 | B14: 許育誠 | C14: 南區服務 | D14: 南區 | E14: 退換貨 | F14: 14 | G14: 在職
A15: E012 | B15: 鄭心妤 | C15: 南區服務 | D15: 南區 | E15: 系統異常 | F15: 14 | G15: 在職
A16: E013 | B16: 謝孟軒 | C16: 南區服務 | D16: 南區 | E16: 帳務問題 | F16: 14 | G16: 在職
A17: E014 | B17: 洪婉婷 | C17: 南區服務 | D17: 南區 | E17: 登入問題 | F17: 14 | G17: 在職
A18: E015 | B18: 郭彥廷 | C18: 南區服務 | D18: 南區 | E18: 訂單問題 | F18: 14 | G18: 在職
A19: E016 | B19: 何佳蓉 | C19: 南區服務 | D19: 南區 | E19: 配送問題 | F19: 14 | G19: 在職
A20: E017 | B20: 羅子晴 | C20: 線上服務 | D20: 全區 | E20: 退換貨 | F20: 18 | G20: 在職
A21: E018 | B21: 宋宇翔 | C21: 線上服務 | D21: 全區 | E21: 系統異常 | F21: 18 | G21: 在職
... A27: E024 | B27: 范家銘 | C27: 線上服務 | D27: 全區 | E27: 系統異常 | F27: 18 | G27: 在職

Sheet SLA標準
A1: SLA 服務標準 | B1: SLA 服務標準 | C1: SLA 服務標準 | D1: SLA 服務標準
A2: 不同優先程度的首次回覆與結案時限，供客服工單公式引用。 | B2: 不同優先程度的首次回覆與結案時限，供客服工單公式引用。 | C2: 不同優先程度的首次回覆與結案時限，供客服工單公式引用。 | D2: 不同優先程度的首次回覆與結案時限，供客服工單公式引用。
A3: 優先程度 | B3: 首次回覆上限（分鐘） | C3: 結案上限（小時） | D3: 說明
A4: 緊急 | B4: 30 | C4: 4 | D4: 影響多數使用者或核心功能
A5: 高 | B5: 60 | C5: 8 | D5: 重要功能受影響，但仍有替代方式
A6: 一般 | B6: 240 | C6: 24 | D6: 一般操作、訂單或服務問題
A7: 低 | B7: 480 | C7: 48 | D7: 諮詢、建議或不影響主要使用的問題

Sheet 滿意度調查
A1: 客服滿意度調查 | B1: 客服滿意度調查 | C1: 客服滿意度調查 | D1: 客服滿意度調查 | E1: 客服滿意度調查 | F1: 客服滿意度調查 | G1: 客服滿意度調查 | H1: 客服滿意度調查 | I1: 客服滿意度調查
A2: 結案後取得的模擬評分與回饋，可依工單編號連接客服工單。 | B2: 結案後取得的模擬評分與回饋，可依工單編號連接客服工單。 | C2: 結案後取得的模擬評分與回饋，可依工單編號連接客服工單。 | D2: 結案後取得的模擬評分與回饋，可依工單編號連接客服工單。 | E2: 結案後取得的模擬評分與回饋，可依工單編號連接客服工單。 | F2: 結案後取得的模擬評分與回饋，可依工單編號連接客服工單。 | G2: 結案後取得的模擬評分與回饋，可依工單編號連接客服工單。 | H2: 結案後取得的模擬評分與回饋，可依工單編號連接客服工單。 | I2: 結案後取得的模擬評分與回饋，可依工單編號連接客服工單。
A3: 調查編號 | B3: 工單編號 | C3: 評分日期 | D3: 整體滿意度 | E3: 回覆速度 | F3: 問題解決 | G3: 服務態度 | H3: 願意推薦 | I3: 客戶意見
A4: SV-2026-0001 | B4: TK-2026-0004 | C4: 46115.949 | D4: 4 | E4: 3 | F4: 5 | G4: 5 | H4: 是 | I4: 服務人員說明很完整
A5: SV-2026-0002 | B5: TK-2026-0005 | C5: 46115.12 | D5: 5 | E5: 5 | F5: 5 | G5: 5 | H5: 是 | I5: 回覆清楚，問題已順利處理
A6: SV-2026-0003 | B6: TK-2026-0007 | C6: 46117.775 | D6: 5 | E6: 5 | F6: 5 | G6: 5 | H6: 是 | I6: 服務人員說明很完整
A7: SV-2026-0004 | B7: TK-2026-0008 | C7: 46116.067 | D7: 3 | E7: 2 | F7: 2 | G7: 4 | H7: 否 | I7: 問題已處理，但等待時間稍長
A8: SV-2026-0005 | B8: TK-2026-0011 | C8: 46116.733 | D8: 3 | E8: 2 | F8: 4 | G8: 4 | H8: 否 | I8: 整體尚可
A9: SV-2026-0006 | B9: TK-2026-0012 | C9: 46117.32 | D9: 4 | E9: 5 | F9: 5 | G9: 5 | H9: 是 | I9: 處理速度符合預期
A10: SV-2026-0007 | B10: TK-2026-0014 | C10: 46117.338 | D10: 3 | E10: 4 | F10: 2 | G10: 4 | H10: 否 | I10: 希望能減少轉接次數
A11: SV-2026-0008 | B11: TK-2026-0015 | C11: 46118.798 | D11: 5 | E11: 5 | F11: 5 | G11: 5 | H11: 是 | I11: 服務人員說明很完整
A12: SV-2026-0009 | B12: TK-2026-0017 | C12: 46118.179 | D12: 5 | E12: 4 | F12: 5 | G12: 5 | H12: 是 | I12: 服務人員說明很完整
A13: SV-2026-0010 | B13: TK-2026-0018 | C13: 46120.605 | D13: 3 | E13: 2 | F13: 2 | G13: 4 | H13: 否 | I13: 希望能減少轉接次數
A14: SV-2026-0011 | B14: TK-2026-0019 | C14: 46118.81 | D14: 3 | E14: 4 | F14: 2 | G14: 3 | H14: 否 | I14: 整體尚可
A15: SV-2026-0012 | B15: TK-2026-0021 | C15: 46119.366 | D15: 4 | E15: 3 | F15: 3 | G15: 5 | H15: 是 | I15: 服務人員說明很完整
... A570: SV-2026-0567 | B570: TK-2026-0871 | C570: 46203.434 | D570: 5 | E570: 4 | F570: 4 | G570: 5 | H570: 是 | I570: 處理速度符合預期
